Workbook

Sheet Input_Sheet
A1: Group | B1: 39 | C1: Please write this out as a digit: 1,2, etc.
A2: ID | B2: cbirrell3 | C2: Georgia Tech LOGIN of submitter: such as JGARNER47 (not private!)
C4: Remember, just submit one file per group!
B6: This file is initially set to automatic formula calculations. Once you begin to build the
B7: interest expense (on the income statement) and the cash and short term debt balances
B8: (which are on the balance sheet), you may want to switch to manual calculations so
B9: that Excel can "handle" the iterative nature of these calculations.

Sheet Historicals -->

Sheet Income Statement
A1: Procter Gamble
A2: CONSOLIDATED STATEMENTS OF EARNINGS - USD ($) $ in Millions | B2: 12 Months Ended
B3: Jun. 30, 2022 | C3: Jun. 30, 2023 | D3: Jun. 30, 2024
A4: Net Sales | B4: 80187 | C4: 82006 | D4: 84039
A5: Cost of Goods and Services Sold | B5: 42157 | C5: 42760 | D5: 40848
A6: Selling, General and Administrative Expense | B6: 20217 | C6: 21112 | D6: 23305
A7: Goodwill & Indefinite Lived Intangible Asset Impairment Charges | D7: 1341
A8: Operating Income (also known as EBIT) | B8: 17813 | C8: 18134 | D8: 18545
A9: Interest Expense | B9: -439 | C9: -756 | D9: -925
A10: Investment Income, Interest | B10: 51 | C10: 307 | D10: 473
A11: Other Nonoperating Income (Expense) | B11: 570 | C11: 668 | D11: 668
A12: Earnings from Continuing Operations Before Income Taxes | B12: 17995 | C12: 18353 | D12: 18761
A13: Income Taxes on Continuing Operations | B13: 3202 | C13: 3615 | D13: 3787
A14: Net Earnings | B14: 14793 | C14: 14738 | D14: 14974
A15: Net Earnings Attributable to Noncontrolling Interest | B15: 51 | C15: 85 | D15: 95
A16: Net Income (Loss) Attributable to Parent | B16: 14742 | C16: 14653 | D16: 14879
A17: BASIC NET EARNINGS PER COMMON SHARE
A18: Earnings Per Share, Basic | B18: 6 | C18: 6.07 | D18: 6.18
A19: DILUTED NET EARNINGS PER COMMON SHARE
A20: Earnings Per Share, Diluted | B20: 5.81 | C20: 5.9 | D20: 6.02
A21: Dividends | B21: 8770 | C21: 8999 | D21: 9312

Sheet Balance Sheet
A1: CONSOLIDATED BALANCE SHEETS - USD ($) shares in Millions, $ in Millions | B1: Jun. 30, 2022 | C1: Jun. 30, 2023 | D1: Jun. 30, 2024
A2: CURRENT ASSETS
A3: Cash, Cash Equivalents, Restricted Cash and Restricted Cash Equivalents | B3: 7214 | C3: 8246 | D3: 9482
A4: Accounts Receivable, after Allowance for Credit Loss, Current | B4: 5143 | C4: 5471 | D4: 6118
A5: INVENTORIES
A6: Inventory, Raw Materials and Supplies, Net of Reserves | B6: 2168 | C6: 1863 | D6: 1617
A7: Inventory, Work in Process, Net of Reserves | B7: 856 | C7: 956 | D7: 929
A8: Inventory, Finished Goods, Net of Reserves | B8: 3900 | C8: 4254 | D8: 4470
A9: Inventory, Net, Total | B9: 6924 | C9: 7073 | D9: 7016
A10: Prepaid Expense and Other Assets, Current | B10: 2372 | C10: 1858 | D10: 2094
A11: Assets, Current | B11: 21653 | C11: 22648 | D11: 24709
A12: Property, Plant and Equipment, Net | B12: 21195 | C12: 21909 | D12: 22152
A13: Goodwill | B13: 39700 | C13: 40659 | D13: 40303
A14: Intangible Assets, Net (Excluding Goodwill) | B14: 23679 | C14: 23783 | D14: 22047
A15: Other Assets, Noncurrent | B15: 10981 | C15: 11830 | D15: 13158
A16: Assets | B16: 117208 | C16: 120829 | D16: 122370
A17: CURRENT LIABILITIES
A18: Accounts Payable, Current | B18: 14882 | C18: 14598 | D18: 15365
A19: Accrued Liabilities, Current | B19: 9554 | C19: 10929 | D19: 11073
A20: Debt, Current | B20: 8645 | C20: 10229 | D20: 7191
A21: Liabilities, Current | B21: 33081 | C21: 35756 | D21: 33627
A22: Long-term Debt, Excluding Current Maturities | B22: 22848 | C22: 24378 | D22: 25269
A23: Deferred Income Tax Liabilities, Net | B23: 6809 | C23: 6478 | D23: 6516
A24: Other Liabilities, Noncurrent | B24: 7616 | C24: 7152 | D24: 6398
A25: Liabilities | B25: 70354 | C25: 73764 | D25: 71811
A26: SHAREHOLDERS' EQUITY
A27: Preferred Stock | B27: 843 | C27: 819 | D27: 798
A28: Common Stock, Value, Issued | B28: 4009 | C28: 4009 | D28: 4009
A29: Additional Paid in Capital | B29: 65795 | C29: 66556 | D29: 67684
A30: Reserve For ESOP Debt Retirement | B30: -916 | C30: -821 | D30: -737
A31: Accumulated Other Comprehensive Income (Loss), Net of Tax | B31: -12189 | C31: -12220 | D31: -11900
A32: Treasury Stock, Value | B32: -123382 | C32: -129736 | D32: -133379
A33: Retained Earnings (Accumulated Deficit) | B33: 112429 | C33: 118170 | D33: 123811
A34: Stockholders' Equity Attributable to Noncontrolling Interest | B34: 265 | C34: 288 | D34: 272
A35: Stockholders' Equity, Including Portion Attributable to Noncontrolling Interest | B35: 46854 | C35: 47065 | D35: 50559
A36: Liabilities and Equity | B36: 117208 | C36: 120829 | D36: 122370
A37: Common Stock, Shares, Issued | B37: 4009.2 | C37: 4009.2 | D37: 4009.2
A38: Common Stock, Par or Stated Value Per Share | B38: 1 | C38: 1 | D38: 1
... A40: Treasury Stock, Shares | B40: 1615.4 | C40: 1647.1 | D40: 1652.2

Sheet Forecasts -->

Sheet IS Hist Forecast
B2: Income Statements | D2: Historical | H2: Forecast
D3: 2022 | E3: =D3+1 -> 2023 | F3: =E3+1 -> 2024 | H3: =F3+1 -> 2025 | I3: =H3+1 -> 2026 | J3: =I3+1 -> 2027 | K3: Col h formulas
B4: Net Sales | D4: {='Income Statement'!B4:D4} -> 80187 | E4: 82006 | F4: 84039 | H4: =(F$4*(1+H18)) -> 89081.34 | I4: =(H$4*(1+I18)) -> 94426.22 | J4: =(I$4*(1+J18)) -> 100091.79 | K4: =_xlfn.FORMULATEXT(H4) -> =(F$4*(1+H18))
B5: Cost of Goods and Services Sold | D5: {='Income Statement'!B5:D5} -> 42157 | E5: 42760 | F5: 40848 | H5: =H$4*H19 -> 43298.88 | I5: =I$4*I19 -> 45896.813 | J5: =J$4*J19 -> 48650.622 | K5: =_xlfn.FORMULATEXT(H5) -> =H$4*H19
B6: Selling, General and Administrative Expense | D6: {='Income Statement'!B6:D6} -> 20217 | E6: 21112 | F6: 23305 | H6: =H$4*H20 -> 23365.426 | I6: =I$4*I20 -> 24767.351 | J6: =J$4*J20 -> 26253.392 | K6: =_xlfn.FORMULATEXT(H6) -> =H$4*H20
B7: Goodwill & Indefinite Lived Intangible Asset Impairment Charges | D7: {='Income Statement'!B7:D7} -> 0 | E7: 0 | F7: 1341 | H7: =H$4*H21 -> 0 | I7: =I$4*I21 -> 0 | J7: =J$4*J21 -> 0 | K7: =_xlfn.FORMULATEXT(H7) -> =H$4*H21
B8: Operating Income (also known as EBIT) | D8: =D4-D5-D6 -> 17813 | E8: =E4-E5-E6 -> 18134 | F8: =F4-F5-F6-F7 -> 18545 | H8: =H4-H5-H6-H7 -> 22417.034 | I8: =I4-I5-I6-I7 -> 23762.056 | J8: =J4-J5-J6-J7 -> 25187.78 | K8: =_xlfn.FORMULATEXT(H8) -> =H4-H5-H6-H7
B9: Net Interest Expense | D9: ='Income Statement'!B9+'Income Statement'!B10 -> -388 | E9: ='Income Statement'!C9+'Income Statement'!C10 -> -449 | F9: ='Income Statement'!D9+'Income Statement'!D10 -> -452 | H9: =-H23*('BAL Hist Forecast'!H19+'BAL Hist Forecast'!H21)+'IS Hist Forecast'!H28*'BAL Hist Forecast'!H4 -> -468.34079 | I9: =-I23*('BAL Hist Forecast'!I19+'BAL Hist Forecast'!I21)+'IS Hist Forecast'!I28*'BAL Hist Forecast'!I4 -> -392.51858 | J9: =-J23*('BAL Hist Forecast'!J19+'BAL Hist Forecast'!J21)+'IS Hist Forecast'!J28*'BAL Hist Forecast'!J4 -> -289.60074 | K9: =_xlfn.FORMULATEXT(H9) -> =-H23*('BAL Hist Forecast'!H19+'BAL Hist Forecast'!H21)+'IS Hist Forecast'!H28*'BAL Hist Forecast'!H4 | L9: Placing a YELLOW background is a good idea when building the model. I use a YELLOW
B10: Other Nonoperating Income (Expense) | D10: {='Income Statement'!B11:D11} -> 570 | E10: 668 | F10: 668 | H10: =H4*H22 -> 688.97943 | I10: =I4*I22 -> 730.3182 | J10: =J4*J22 -> 774.13729 | K10: =_xlfn.FORMULATEXT(H10) -> =H4*H22 | L10: background for any number I initially "hardcode" as a reminder I need to write a formula later!
B11: Earnings from Continuing Operations Before Income Taxes | D11: =SUM(D8:D10) -> 17995 | E11: =SUM(E8:E10) -> 18353 | F11: =SUM(F8:F10) -> 18761 | H11: =H8+H9+H10 -> 22637.673 | I11: =I8+I9+I10 -> 24099.856 | J11: =J8+J9+J10 -> 25672.316 | K11: =_xlfn.FORMULATEXT(H11) -> =H8+H9+H10
B12: Income Taxes on Continuing Operations | D12: {='Income Statement'!B13:D13} -> 3202 | E12: 3615 | F12: 3787 | H12: =H11*H24 -> 4527.5346 | I12: =I11*I24 -> 4819.9712 | J12: =J11*J24 -> 5134.4633 | K12: =_xlfn.FORMULATEXT(H12) -> =H11*H24
B13: Net Earnings | D13: =D11-D12 -> 14793 | E13: =E11-E12 -> 14738 | F13: =F11-F12 -> 14974 | H13: =H11-H12 -> 18110.138 | I13: =I11-I12 -> 19279.885 | J13: =J11-J12 -> 20537.853 | K13: =_xlfn.FORMULATEXT(H13) -> =H11-H12
B14: Net Earnings Attributable to Noncontrolling Interest | D14: {='Income Statement'!B15:D15} -> 51 | E14: 85 | F14: 95 | L14: No need to forecast earnings attributable to non-controlling interest
B15: Net Income (Loss) Attributable to Parent | D15: =D13-D14 -> 14742 | E15: =E13-E14 -> 14653 | F15: =F13-F14 -> 14879 | H15: =H13 -> 18110.138 | I15: =I13 -> 19279.885 | J15: =J13 -> 20537.853 | K15: =_xlfn.FORMULATEXT(H15) -> =H13
B16: Dividends (Common) | D16: {='Income Statement'!B21:D21} -> 8770 | E16: 8999 | F16: 9312 | H16: =IF(H27=1,H26,H15*H25) -> 9312 | I16: =IF(I27=1,I26,I15*I25) -> 9312 | J16: =IF(J27=1,J26,J15*J25) -> 9312 | K16: =_xlfn.FORMULATEXT(H16) -> =IF(H27=1,H26,H15*H25)
B18: Revenue growth | E18: =(E4-D4)/D$4 -> 0.022684475 | F18: =(F4-E4)/E$4 -> 0.024790869 | H18: 0.06 | I18: 0.06 | J18: 0.06
B19: COGS % Revenues | D19: =D5/D$4 -> 0.5257336 | E19: =E5/E$4 -> 0.52142526 | F19: =F5/F$4 -> 0.48606004 | H19: =$F$19 -> 0.48606004 | I19: =$F$19 -> 0.48606004 | J19: =$F$19 -> 0.48606004 | L19: Use 2024 data as per analysts (not average)
B20: SG&A % Revenues | D20: =D6/D$4 -> 0.25212316 | E20: =E6/E$4 -> 0.25744458 | F20: =F6/F$4 -> 0.27731172 | H20: =AVERAGE($D$20:$F$20) -> 0.26229315 | I20: =AVERAGE($D$20:$F$20) -> 0.26229315 | J20: =AVERAGE($D$20:$F$20) -> 0.26229315
B21: Goodwill Impairment % Revenues | D21: =D7/D$4 -> 0 | E21: =E7/E$4 -> 0 | F21: =F7/F$4 -> 0.015956877 | H21: 0 | I21: 0 | J21: 0 | L21: Assume 0% going forward
B22: Other non-operating income, net % Revenues | D22: =D10/D$4 -> 0.0071083842 | E22: =E10/E$4 -> 0.0081457454 | F22: =F10/F$4 -> 0.0079486905 | H22: =AVERAGE($D$22:$F$22) -> 0.0077342734 | I22: =AVERAGE($D$22:$F$22) -> 0.0077342734 | J22: =AVERAGE($D$22:$F$22) -> 0.0077342734
B23: Interest % ST and LT Debt | H23: 0.025 | I23: 0.025 | J23: 0.025
B24: Tax rate (% of EBT) | D24: =D12/D11 -> 0.17793832 | E24: =E12/E11 -> 0.19697052 | F24: =F12/F11 -> 0.20185491 | H24: 0.2 | I24: 0.2 | J24: 0.2
B25: Payout ratios | D25: =D16/D15 -> 0.59489893 | E25: =E16/E15 -> 0.61414045 | F25: =F16/F15 -> 0.62584851 | H25: =$F$25 -> 0.62584851 | I25: =$F$25 -> 0.62584851 | J25: =$F$25 -> 0.62584851
B26: Dividends ($) | D26: {='Income Statement'!B21:D21} -> 8770 | E26: 8999 | F26: 9312 | H26: 9312 | I26: 9312 | J26: 9312 | L26: Please read case instructions about dividend forecast!
B27: Dividend 0/1 | H27: 1 | I27: 1 | J27: 1 | L27: Please read case instructions about dividend forecast!
B28: Interest % Cash | H28: 0.03 | I28: 0.03 | J28: 0.03

Sheet CF Statement Forecast
B2: Consolidated Statements of Cash Flows - USD ($) | D2: Forecast
B3: $ in Millions | D3: 2025 | E3: =D3+1 -> 2026 | F3: =E3+1 -> 2027
B5: Cash flows from operating activities:
B6: Net earnings | D6: ='IS Hist Forecast'!H13 -> 18110.138 | E6: ='IS Hist Forecast'!I13 -> 19279.885 | F6: ='IS Hist Forecast'!J13 -> 20537.853
B7: Adjustments to reconcile net earnings to operating cash flow
B8: Deferred income taxes | D8: ='BAL Hist Forecast'!H22 - 'BAL Hist Forecast'!F22 -> 653.37502 | E8: ='BAL Hist Forecast'!I22 - 'BAL Hist Forecast'!H22 -> 430.1625 | F8: ='BAL Hist Forecast'!J22 - 'BAL Hist Forecast'!I22 -> 455.97225
B9: Other long term liabilities | D9: ='BAL Hist Forecast'!H23 - 'BAL Hist Forecast'!F23 -> 1272.5697 | E9: ='BAL Hist Forecast'!I23 - 'BAL Hist Forecast'!H23 -> 460.23418 | F9: ='BAL Hist Forecast'!J23 - 'BAL Hist Forecast'!I23 -> 487.84823
B10: Accounts receivable | D10: =-('BAL Hist Forecast'!H5 - 'BAL Hist Forecast'!F5) -> 70.809959 | E10: =-('BAL Hist Forecast'!I5 - 'BAL Hist Forecast'!H5) -> -362.8314 | F10: =-('BAL Hist Forecast'!J5 - 'BAL Hist Forecast'!I5) -> -384.60129
B11: Inventories | D11: =-('BAL Hist Forecast'!H10 - 'BAL Hist Forecast'!F10) -> -220.881 | E11: =-('BAL Hist Forecast'!I10 - 'BAL Hist Forecast'!H10) -> -434.21286 | F11: =-('BAL Hist Forecast'!J10 - 'BAL Hist Forecast'!I10) -> -460.26563
B12: Other current assets | D12: =-('BAL Hist Forecast'!H11 - 'BAL Hist Forecast'!F11) -> -197.01577 | E12: =-('BAL Hist Forecast'!I11 - 'BAL Hist Forecast'!H11) -> -137.46095 | F12: =-('BAL Hist Forecast'!J11 - 'BAL Hist Forecast'!I11) -> -145.7086
B13: Accounts payable and accrued liabilities | D13: ='BAL Hist Forecast'!H17 - 'BAL Hist Forecast'!F17 + 'BAL Hist Forecast'!H18 - 'BAL Hist Forecast'!F18 -> 421.00495 | E13: ='BAL Hist Forecast'!I17 - 'BAL Hist Forecast'!H17 + 'BAL Hist Forecast'!I18 - 'BAL Hist Forecast'!H18 -> 1611.5403 | F13: ='BAL Hist Forecast'!J17 - 'BAL Hist Forecast'!I17 + 'BAL Hist Forecast'!J18 - 'BAL Hist Forecast'!I18 -> 1708.2327
B14: ESOP | D14: ='BAL Hist Forecast'!H28 - 'BAL Hist Forecast'!F28 -> 65 | E14: ='BAL Hist Forecast'!I28 - 'BAL Hist Forecast'!H28 -> 65 | F14: ='BAL Hist Forecast'!J28 - 'BAL Hist Forecast'!I28 -> 65
B15: Net cash provided by operating activities | D15: =SUM(D6:D14) -> 20175.001 | E15: =SUM(E6:E14) -> 20912.317 | F15: =SUM(F6:F14) -> 22264.331
B17: Cash flows from investing activities:
B18: Purchase/sale of plant assets | D18: =-('BAL Hist Forecast'!H13-'BAL Hist Forecast'!F13+'BAL Hist Forecast'!H14-'BAL Hist Forecast'!F14) -> -3418.9549 | E18: =-('BAL Hist Forecast'!I13-'BAL Hist Forecast'!H13+'BAL Hist Forecast'!I14-'BAL Hist Forecast'!H14) -> -4568.3603 | F18: =-('BAL Hist Forecast'!J13-'BAL Hist Forecast'!I13+'BAL Hist Forecast'!J14-'BAL Hist Forecast'!I14) -> -4837.4032
B19: Net cash used in investing activities | D19: =SUM(D18) -> -3418.9549 | E19: =SUM(E18) -> -4568.3603 | F19: =SUM(F18) -> -4837.4032
B21: Cash flows from financing activities:
B22: Net short-term borrowings (repayments) | D22: ='BAL Hist Forecast'!H19-'BAL Hist Forecast'!F19 -> 3073.9536 | E22: ='BAL Hist Forecast'!I19-'BAL Hist Forecast'!H19 -> -3031.9562 | F22: ='BAL Hist Forecast'!J19-'BAL Hist Forecast'!I19 -> -4114.9275
B23: Long-term borrowings (repayments) | D23: ='BAL Hist Forecast'!H21-'BAL Hist Forecast'!F21 -> 0 | E23: ='BAL Hist Forecast'!I21-'BAL Hist Forecast'!H21 -> 0 | F23: ='BAL Hist Forecast'!J21-'BAL Hist Forecast'!I21 -> 0
B24: Issuance of common stock | D24: ='BAL Hist Forecast'!H27-'BAL Hist Forecast'!F27 -> 0 | E24: ='BAL Hist Forecast'!I27-'BAL Hist Forecast'!H27 -> 0 | F24: ='BAL Hist Forecast'!J27-'BAL Hist Forecast'!I27 -> 0
B25: Issuance of preferred stock | D25: ='BAL Hist Forecast'!H26-'BAL Hist Forecast'!F26 -> 0 | E25: ='BAL Hist Forecast'!I26-'BAL Hist Forecast'!H26 -> 0 | F25: ='BAL Hist Forecast'!J26-'BAL Hist Forecast'!I26 -> 0
B26: Dividends paid | D26: =-'IS Hist Forecast'!H16 -> -9312 | E26: =-'IS Hist Forecast'!I16 -> -9312 | F26: =-'IS Hist Forecast'!J16 -> -9312
B27: Treasury stock purchases | D27: ='BAL Hist Forecast'!H30-'BAL Hist Forecast'!F30 -> -6000 | E27: ='BAL Hist Forecast'!I30-'BAL Hist Forecast'!H30 -> -4000 | F27: ='BAL Hist Forecast'!J30-'BAL Hist Forecast'!I30 -> -4000
B28: Net cash used in financing activities | D28: =SUM(D22:D27) -> -12238.046 | E28: =SUM(E22:E27) -> -16343.956 | F28: =SUM(F22:F27) -> -17426.928
B30: Total change in cash | D30: =D28+D19+D15 -> 4518 | E30: =E28+E19+E15 -> -2.910383e-11 | F30: =F28+F19+F15 -> 0
B31: Cash and cash equivalents continuing operations - beginning of period | D31: ='BAL Hist Forecast'!F4 -> 9482 | E31: ='BAL Hist Forecast'!H4 -> 14000 | F31: ='BAL Hist Forecast'!I4 -> 14000
B32: Cash and cash equivalents continuing operations - end of period | D32: =SUM(D30:D31) -> 14000 | E32: =E30+E31 -> 14000 | F32: =F30+F31 -> 14000
B34: Checks to Balance sheet? | D34: =IF(ROUND(D32,0)=ROUND('BAL Hist Forecast'!H4,0),"YES","NO") -> YES | E34: =IF(ROUND(E32,0)=ROUND('BAL Hist Forecast'!I4,0),"YES","NO") -> YES | F34: =IF(ROUND(F32,0)=ROUND('BAL Hist Forecast'!J4,0),"YES","NO") -> YES

Sheet BAL Hist Forecast
B2: CONSOLIDATED BALANCE SHEETS - USD ($) shares in Millions, $ in Millions | D2: Historicals | H2: Forecast
B3: CURRENT ASSETS | D3: Jun. 30, 2022 | E3: Jun. 30, 2023 | F3: Jun. 30, 2024 | H3: 2025 | I3: =H3+1 -> 2026 | J3: =I3+1 -> 2027 | K3: Simplified formula for Cell H4 | L3: =H3 -> 2025 | M3: =I3 -> 2026 | N3: =J3 -> 2027 | O3: Formulas for 2024 blue/green)
B4: Cash, Cash Equivalents, Restricted Cash and Restricted Cash Equivalents | D4: {='Balance Sheet'!B3:D3} -> 7214 | E4: 8246 | F4: 9482 | H4: =IF(L4>L5,H43,(L5-L4+H43)) -> 14000 | I4: =IF(M4>M5,I43,(M5-M4+I43)) -> 14000 | J4: =IF(N4>N5,J43,(N5-N4+J43)) -> 14000 | K4: =_xlfn.FORMULATEXT(H4) -> =IF(L4>L5,H43,(L5-L4+H43)) | L4: =H43+H5+H10+H11+H13+H14 -> 130654.04 | M4: =I43+I5+I10+I11+I13+I14 -> 136156.91 | N4: =J43+J5+J10+J11+J13+J14 -> 141984.89 | O4: =_xlfn.FORMULATEXT(L4) -> =H43+H5+H10+H11+H13+H14
B5: Accounts Receivable, after Allowance for Credit Loss, Current | D5: {='Balance Sheet'!B4:D4} -> 5143 | E5: 5471 | F5: 6118 | H5: ='IS Hist Forecast'!H4/365*'BAL Hist Forecast'!H44 -> 6047.19 | I5: ='IS Hist Forecast'!I4/365*'BAL Hist Forecast'!I44 -> 6410.0214 | J5: ='IS Hist Forecast'!J4/365*'BAL Hist Forecast'!J44 -> 6794.6227 | K5: =_xlfn.FORMULATEXT(H5) -> ='IS Hist Forecast'!H4/365*'BAL Hist Forecast'!H44 | L5: =H17+H18+SUM(H21:H23)+H26+H27+H28+H29+H30+H31+H32 -> 120389.09 | M5: =I17+I18+SUM(I21:I23)+I26+I27+I28+I29+I30+I31+I32 -> 128923.91 | N5: =J17+J18+SUM(J21:J23)+J26+J27+J28+J29+J30+J31+J32 -> 138866.82 | O5: =_xlfn.FORMULATEXT(L5) -> =H17+H18+SUM(H21:H23)+H26+H27+H28+H29+H30+H31+H32
B6: INVENTORIES | L6: Cell L4 is all assets and Cell L5 is all L + E except short term debt
B7: Inventory, Raw Materials and Supplies, Net of Reserves | D7: {='Balance Sheet'!B6:D6} -> 2168 | E7: 1863 | F7: 1617 | H7: ='IS Hist Forecast'!H$5/365*'BAL Hist Forecast'!H45 -> 1942.4072 | I7: ='IS Hist Forecast'!I5/365*'BAL Hist Forecast'!I45 -> 2058.9516 | J7: ='IS Hist Forecast'!J5/365*'BAL Hist Forecast'!J45 -> 2182.4887 | K7: =_xlfn.FORMULATEXT(H7) -> ='IS Hist Forecast'!H$5/365*'BAL Hist Forecast'!H45
B8: Inventory, Work in Process, Net of Reserves | D8: {='Balance Sheet'!B7:D7} -> 856 | E8: 956 | F8: 929 | H8: ='IS Hist Forecast'!H$5/365*'BAL Hist Forecast'!H46 -> 943.99129 | I8: ='IS Hist Forecast'!I$5/365*'BAL Hist Forecast'!I46 -> 1000.6308 | J8: ='IS Hist Forecast'!J$5/365*'BAL Hist Forecast'!J46 -> 1060.6686 | K8: =_xlfn.FORMULATEXT(H8) -> ='IS Hist Forecast'!H$5/365*'BAL Hist Forecast'!H46
B9: Inventory, Finished Goods, Net of Reserves | D9: {='Balance Sheet'!B8:D8} -> 3900 | E9: 4254 | F9: 4470 | H9: ='IS Hist Forecast'!H$5/365*'BAL Hist Forecast'!H47 -> 4350.4825 | I9: ='IS Hist Forecast'!I$5/365*'BAL Hist Forecast'!I47 -> 4611.5115 | J9: ='IS Hist Forecast'!J$5/365*'BAL Hist Forecast'!J47 -> 4888.2022 | K9: =_xlfn.FORMULATEXT(H9) -> ='IS Hist Forecast'!H$5/365*'BAL Hist Forecast'!H47
B10: Inventory, Net, Total | D10: =SUM(D7:D9) -> 6924 | E10: =SUM(E7:E9) -> 7073 | F10: =SUM(F7:F9) -> 7016 | H10: =SUM(H7:H9) -> 7236.881 | I10: =SUM(I7:I9) -> 7671.0939 | J10: =SUM(J7:J9) -> 8131.3595 | K10: =_xlfn.FORMULATEXT(H10) -> =SUM(H7:H9)
B11: Prepaid Expense and Other Assets, Current | D11: {='Balance Sheet'!B10:D10} -> 2372 | E11: 1858 | F11: 2094 | H11: =H48*'IS Hist Forecast'!H4 -> 2291.0158 | I11: =I48*'IS Hist Forecast'!I4 -> 2428.4767 | J11: =J48*'IS Hist Forecast'!J4 -> 2574.1853 | K11: =_xlfn.FORMULATEXT(H11) -> =H48*'IS Hist Forecast'!H4
B12: Assets, Current | D12: =D10+D11+D4+D5 -> 21653 | E12: =E10+E11+E4+E5 -> 22648 | F12: =F10+F11+F4+F5 -> 24710 | H12: =H4+H5+H10+H11 -> 29575.087 | I12: =I4+I5+I10+I11 -> 30509.592 | J12: =J4+J5+J10+J11 -> 31500.168 | K12: =_xlfn.FORMULATEXT(H12) -> =H4+H5+H10+H11
B13: Property, Plant and Equipment, Net | D13: ='Balance Sheet'!B12+'Balance Sheet'!B13+'Balance Sheet'!B14 -> 84574 | E13: ='Balance Sheet'!C12+'Balance Sheet'!C13+'Balance Sheet'!C14 -> 86351 | F13: ='Balance Sheet'!D12+'Balance Sheet'!D13+'Balance Sheet'!D14 -> 84502 | H13: =F13+H49*('IS Hist Forecast'!H8 - 'IS Hist Forecast'!H12) -> 88079.9 | I13: =H13+I49*('IS Hist Forecast'!I8 - 'IS Hist Forecast'!I12) -> 91868.317 | J13: =I13+J49*('IS Hist Forecast'!J8 - 'IS Hist Forecast'!J12) -> 95878.98 | K13: =_xlfn.FORMULATEXT(H13) -> =F13+H49*('IS Hist Forecast'!H8 - 'IS Hist Forecast'!H12)
B14: Other Assets, Noncurrent | D14: {='Balance Sheet'!B15:D15} -> 10981 | E14: 11830 | F14: 13158 | H14: =H50*'IS Hist Forecast'!H4 -> 12999.055 | I14: =I50*'IS Hist Forecast'!I4 -> 13778.998 | J14: =J50*'IS Hist Forecast'!J4 -> 14605.738 | K14: =_xlfn.FORMULATEXT(H14) -> =H50*'IS Hist Forecast'!H4
B15: Assets | D15: =SUM(D12:D15) -> 117208 | E15: =SUM(E12:E15) -> 120829 | F15: =SUM(F12:F15) -> 122370 | H15: =SUM(H12:H14) -> 130654.04 | I15: =SUM(I12:I14) -> 136156.91 | J15: =SUM(J12:J14) -> 141984.89 | K15: =_xlfn.FORMULATEXT(H15) -> =SUM(H12:H14)
B16: CURRENT LIABILITIES
B17: Accounts Payable, Current | D17: {='Balance Sheet'!B18:D18} -> 14882 | E17: 14598 | F17: 15365 | H17: =H51*'IS Hist Forecast'!H5/365 -> 15451.323 | I17: =I51*'IS Hist Forecast'!I5/365 -> 16378.403 | J17: =J51*'IS Hist Forecast'!J5/365 -> 17361.107 | K17: Simplified formula for H19
B18: Accrued Liabilities, Current | D18: {='Balance Sheet'!B19:D19} -> 9554 | E18: 10929 | F18: 11073 | H18: =H52*'IS Hist Forecast'!H4 -> 11407.682 | I18: =I52*'IS Hist Forecast'!I4 -> 12092.143 | J18: =J52*'IS Hist Forecast'!J4 -> 12817.671 | K18: Simplified formula for H19 | L18: =L3 -> 2025 | M18: =M3 -> 2026 | N18: =N3 -> 2027 | O18: Formulas for 2024 blue/green)
B19: Debt, Current | D19: {='Balance Sheet'!B20:D20} -> 8645 | E19: 10229 | F19: 7191 | H19: =IF((L19-L20)>0,L19-L20,0) -> 10264.954 | I19: =IF((M19-M20)>0,M19-M20,0) -> 7232.9974 | J19: =IF((N19-N20)>0,N19-N20,0) -> 3118.0699 | K19: =_xlfn.FORMULATEXT(H19) -> =IF((L19-L20)>0,L19-L20,0) | L19: =L4 -> 130654.04 | M19: =M4 -> 136156.91 | N19: =N4 -> 141984.89 | O19: =_xlfn.FORMULATEXT(L19) -> =L4
B20: Liabilities, Current | D20: =SUM(D17:D19) -> 33081 | E20: =SUM(E17:E19) -> 35756 | F20: =SUM(F17:F19) -> 33629 | H20: =SUM(H17:H19) -> 37123.959 | I20: =SUM(I17:I19) -> 35703.543 | J20: =SUM(J17:J19) -> 33296.848 | K20: =_xlfn.FORMULATEXT(H20) -> =SUM(H17:H19) | L20: =L5 -> 120389.09 | M20: =M5 -> 128923.91 | N20: =N5 -> 138866.82 | O20: =_xlfn.FORMULATEXT(L20) -> =L5
B21: Long-term Debt, Excluding Current Maturities | D21: {='Balance Sheet'!B22:D22} -> 22848 | E21: 24378 | F21: 25269 | H21: =F21+H53-H54 -> 25269 | I21: =H21+I53-I54 -> 25269 | J21: =I21+J53-J54 -> 25269 | K21: =_xlfn.FORMULATEXT(H21) -> =F21+H53-H54
B22: Deferred Income Tax Liabilities, Net | D22: {='Balance Sheet'!B23:D24} -> 6809 | E22: 6478 | F22: 6516 | H22: ='IS Hist Forecast'!H4*'BAL Hist Forecast'!H55 -> 7169.375 | I22: ='IS Hist Forecast'!I4*'BAL Hist Forecast'!I55 -> 7599.5375 | J22: ='IS Hist Forecast'!J4*'BAL Hist Forecast'!J55 -> 8055.5098 | K22: =_xlfn.FORMULATEXT(H22) -> ='IS Hist Forecast'!H4*'BAL Hist Forecast'!H55
B23: Other Liabilities, Noncurrent | D23: 7616 | E23: 7152 | F23: 6398 | H23: =H56*'IS Hist Forecast'!H4 -> 7670.5697 | I23: =I56*'IS Hist Forecast'!I4 -> 8130.8039 | J23: =J56*'IS Hist Forecast'!J4 -> 8618.6521 | K23: =_xlfn.FORMULATEXT(H23) -> =H56*'IS Hist Forecast'!H4
B24: Liabilities | D24: =SUM(D20:D24) -> 70354 | E24: =SUM(E20:E24) -> 73764 | F24: =SUM(F20:F24) -> 71812 | H24: =SUM(H20:H23) -> 77232.903 | I24: =SUM(I20:I23) -> 76702.884 | J24: =SUM(J20:J23) -> 75240.01 | K24: =_xlfn.FORMULATEXT(H24) -> =SUM(H20:H23)
B25: SHAREHOLDERS' EQUITY
B26: Preferred Stock | D26: {='Balance Sheet'!B27:D27} -> 843 | E26: 819 | F26: 798 | H26: =F26+H57 -> 798 | I26: =H26+I57 -> 798 | J26: =I26+J57 -> 798 | K26: =_xlfn.FORMULATEXT(H26) -> =F26+H57
B27: Common Stock, Par + Additional Paid in Capital | D27: =SUM('Balance Sheet'!B28:B29) -> 69804 | E27: =SUM('Balance Sheet'!C28:C29) -> 70565 | F27: =SUM('Balance Sheet'!D28:D29) -> 71693 | H27: =F27+H57 -> 71693 | I27: =H27+I57 -> 71693 | J27: =I27+J57 -> 71693 | K27: =_xlfn.FORMULATEXT(H27) -> =F27+H57
B28: Reserve For ESOP Debt Retirement | D28: {='Balance Sheet'!B30:D32} -> -916 | E28: -821 | F28: -737 | H28: =F28+H59 -> -672 | I28: =H28+I59 -> -607 | J28: =I28+J59 -> -542 | K28: =_xlfn.FORMULATEXT(H28) -> =F28+H59
B29: Accumulated Other Comprehensive Income (Loss), Net of Tax | D29: -12189 | E29: -12220 | F29: -11900 | H29: =F29+H60 -> -11900 | I29: =H29+I60 -> -11900 | J29: =I29+J60 -> -11900 | K29: =_xlfn.FORMULATEXT(H29) -> =F29+H60
B30: Treasury Stock, Value | D30: -123382 | E30: -129736 | F30: -133379 | H30: =F30-H58 -> -139379 | I30: =H30-I58 -> -143379 | J30: =I30-J58 -> -147379 | K30: =_xlfn.FORMULATEXT(H30) -> =F30-H58
B31: Retained Earnings (Accumulated Deficit) | D31: {='Balance Sheet'!B33:D34} -> 112429 | E31: 118170 | F31: 123811 | H31: =F31+('IS Hist Forecast'!H13-'IS Hist Forecast'!H16) -> 132609.14 | I31: =H31+('IS Hist Forecast'!I13-'IS Hist Forecast'!I16) -> 142577.02 | J31: =I31+('IS Hist Forecast'!J13-'IS Hist Forecast'!J16) -> 153802.88 | K31: =_xlfn.FORMULATEXT(H31) -> =F31+('IS Hist Forecast'!H13-'IS Hist Forecast'!H16)
B32: Stockholders' Equity Attributable to Noncontrolling Interest | D32: 265 | E32: 288 | F32: 272 | H32: =F32+H61 -> 272 | I32: =H32+I61 -> 272 | J32: =I32+J61 -> 272 | K32: =_xlfn.FORMULATEXT(H32) -> =F32+H61 | L32: Even if you keep non-controlling interest constant, the 2023 balance should be 2022 balance PLUS what you are forecasting below! (Row 61)
B33: Stockholders' Equity, Including Portion Attributable to Noncontrolling Interest | D33: =SUM(D26:D32) -> 46854 | E33: =SUM(E26:E32) -> 47065 | F33: =SUM(F26:F32) -> 50558 | H33: =SUM(H26:H32) -> 53421.138 | I33: =SUM(I26:I32) -> 59454.023 | J33: =SUM(J26:J32) -> 66744.876 | K33: =_xlfn.FORMULATEXT(H33) -> =SUM(H26:H32) | L33: The above statement is true for all balance sheet items…that is, even if it stays constant, the formula should be PRIOR balance PLUS the CHANGE (in the input section below)
B34: Liabilities and Equity | D34: =D24+D33 -> #NAME? | E34: =E24+E33 -> 120829 | F34: =F24+F33 -> 122370 | H34: =H33+H24 -> 130654.04 | I34: =I33+I24 -> 136156.91 | J34: =J33+J24 -> 141984.89 | K34: =_xlfn.FORMULATEXT(H34) -> =H33+H24
B36: Common Stock, Shares, Issued | D36: {='Balance Sheet'!B37:D40} -> 4009.2 | E36: 4009.2 | F36: 4009.2
B37: Common Stock, Par or Stated Value Per Share | D37: 1 | E37: 1 | F37: 1
B38: Common Stock, Shares Authorized | D38: 10000 | E38: 10000 | F38: 10000
B39: Treasury Stock, Shares | D39: 1615.4 | E39: 1647.1 | F39: 1652.2
B42: Assumptions
A43: A | B43: Minimum cash balance | H43: 14000 | I43: 14000 | J43: 14000
A44: A | B44: Accounts Receivable, after Allowance for Credit Loss, Current | D44: =D5/('IS Hist Forecast'!D4/365) -> 23.410216 | E44: =E5/('IS Hist Forecast'!E4/365) -> 24.35084 | F44: =F5/('IS Hist Forecast'!F4/365) -> 26.57183 | H44: =AVERAGE($D44:$F44) -> 24.777629 | I44: =AVERAGE($D44:$F44) -> 24.777629 | J44: =AVERAGE($D44:$F44) -> 24.777629 | K44: =_xlfn.FORMULATEXT(H44) -> =AVERAGE($D44:$F44)
...

Sheet Valuations -->

Sheet DCF Analysis
B1: Discounted Cash Flow Analysis
D3: 2025 | E3: =D3+1 -> 2026 | F3: =E3+1 -> 2027
B5: EBIT | D5: ='IS Hist Forecast'!H8 -> 22417.034 | E5: ='IS Hist Forecast'!I8 -> 23762.056 | F5: ='IS Hist Forecast'!J8 -> 25187.78
B6: Taxes expensed | D6: ='IS Hist Forecast'!H12 -> 4527.5346 | E6: ='IS Hist Forecast'!I12 -> 4819.9712 | F6: ='IS Hist Forecast'!J12 -> 5134.4633
B7: Deferred taxes | D7: ='CF Statement Forecast'!D8 -> 653.37502 | E7: ='CF Statement Forecast'!E8 -> 430.1625 | F7: ='CF Statement Forecast'!F8 -> 455.97225
B8: Change in Long term liabilities | D8: ='CF Statement Forecast'!D9 -> 1272.5697 | E8: ='CF Statement Forecast'!E9 -> 460.23418 | F8: ='CF Statement Forecast'!F9 -> 487.84823
B9: EBIT after tax | D9: =D5-D6+D7+D8 -> 19815.444 | E9: =E5-E6+E7+E8 -> 19832.482 | F9: =F5-F6+F7+F8 -> 20997.137
B11: Change in net working capital | D11: ='Supporting Schedules'!E15 -> -73.918133 | E11: ='Supporting Schedules'!F15 -> -677.03509 | F11: ='Supporting Schedules'!G15 -> -717.65719
B12: Net capital expenditures | D12: ='Supporting Schedules'!E18 -> 3418.9549 | E12: ='Supporting Schedules'!F18 -> 4568.3603 | F12: ='Supporting Schedules'!G18 -> 4837.4032
B14: FCF | D14: =D9-D11-D12 -> 16470.408 | E14: =E9-E11-E12 -> 15941.157 | F14: =F9-F11-F12 -> 16877.391
B15: Terminal value | F15: =F14*(1+WACC_growth_HARDCODE!B2)/(WACC_growth_HARDCODE!B1-WACC_growth_HARDCODE!B2) -> 433537.98
B16: Total CFs | E16: =SUM(E14:E15) -> 15941.157 | F16: =SUM(F14:F15) -> 450415.37
B19: Value of the firm | D19: =NPV(WACC_growth_HARDCODE!B1,'DCF Analysis'!D16:F16) -> 399680.22 | E19: Market value of firm
B20: Less value of debt/preferred/net of cash | D20: ='BAL Hist Forecast'!F19 + 'BAL Hist Forecast'!F21 + 'BAL Hist Forecast'!F26 - 'BAL Hist Forecast'!F4 -> 23776 | E20: MV Debt + MV Preferred - Cash | H20: For Case #2, we use book value of debt , preferred stock and cash
B21: Value of equity | D21: =D19-D20 -> 375904.22 | E21: MV equity | H21: In Case #4, we use market value of debt, book value of preferred, book value of cash
B22: Per share price | D22: =D21/WACC_growth_HARDCODE!B3 -> 159.48418 | E22: estimate as of June 30, 2024

Sheet Support -->

Sheet Supporting Schedules
A1: Supporting schedules: Change in NWC and Net Capital Expenditures
D2: 2024 | E2: =D2+1 -> 2025 | F2: =E2+1 -> 2026 | G2: =F2+1 -> 2027
A4: Net working Capital
A5: Accounts Receivable | D5: ='BAL Hist Forecast'!F5 -> 6118 | E5: ='BAL Hist Forecast'!H5 -> 6047.19 | F5: ='BAL Hist Forecast'!I5 -> 6410.0214 | G5: ='BAL Hist Forecast'!J5 -> 6794.6227
A6: Inventory | D6: ='BAL Hist Forecast'!F10 -> 7016 | E6: ='BAL Hist Forecast'!H10 -> 7236.881 | F6: ='BAL Hist Forecast'!I10 -> 7671.0939 | G6: ='BAL Hist Forecast'!J10 -> 8131.3595
A7: Other current assets | D7: ='BAL Hist Forecast'!F11 -> 2094 | E7: ='BAL Hist Forecast'!H11 -> 2291.0158 | F7: ='BAL Hist Forecast'!I11 -> 2428.4767 | G7: ='BAL Hist Forecast'!J11 -> 2574.1853
A8: Total Current assets | D8: =SUM(D5:D7) -> 15228 | E8: =SUM(E5:E7) -> 15575.087 | F8: =SUM(F5:F7) -> 16509.592 | G8: =SUM(G5:G7) -> 17500.168
A10: Accounts payable/accruals | D10: ='BAL Hist Forecast'!F17 + 'BAL Hist Forecast'!F18 -> 26438 | E10: ='BAL Hist Forecast'!H17 + 'BAL Hist Forecast'!H18 -> 26859.005 | F10: ='BAL Hist Forecast'!I17 + 'BAL Hist Forecast'!I18 -> 28470.545 | G10: ='BAL Hist Forecast'!J17 + 'BAL Hist Forecast'!J18 -> 30178.778
A11: Total Current liabilities | D11: =SUM(D10) -> 26438 | E11: =SUM(E10) -> 26859.005 | F11: =SUM(F10) -> 28470.545 | G11: =SUM(G10) -> 30178.778
A13: NWC | D13: =D8-D11 -> -11210 | E13: =E8-E11 -> -11283.918 | F13: =F8-F11 -> -11960.953 | G13: =G8-G11 -> -12678.61
A15: Change NWC | E15: =E13-D13 -> -73.918133 | F15: =F13-E13 -> -677.03509 | G15: =G13-F13 -> -717.65719
A18: Capital Expenditures | E18: ='BAL Hist Forecast'!H13+'BAL Hist Forecast'!H14-'BAL Hist Forecast'!F13-'BAL Hist Forecast'!F14 -> 3418.9549 | F18: ='BAL Hist Forecast'!I13+'BAL Hist Forecast'!I14-'BAL Hist Forecast'!H13-'BAL Hist Forecast'!H14 -> 4568.3603 | G18: ='BAL Hist Forecast'!J13+'BAL Hist Forecast'!J14-'BAL Hist Forecast'!I13-'BAL Hist Forecast'!I14 -> 4837.4032

Sheet Comparable_Analysis_Football-->

Sheet Football Field
B2: Church & Dwight | C2: STEPAN | D2: Johnson & Johnson | E2: Pepsi | H2: Min | I2: Quartile 1 | J2: Median | K2: Quartile 3 | L2: Max | O2: Min | P2: Quartile 1 | Q2: Median | R2: Quartile 3 | S2: Max
A3: P/E | B3: ='Multiple Valuation'!G21 -> 0 | C3: ='Multiple Valuation'!G37 -> 0 | D3: ='Multiple Valuation'!G53 -> 0 | E3: ='Multiple Valuation'!G69 -> 0 | G3: P/E | N3: P/E
A4: P/B | B4: ='Multiple Valuation'!G20 -> 0 | C4: ='Multiple Valuation'!G36 -> 0 | D4: ='Multiple Valuation'!G52 -> 0 | E4: ='Multiple Valuation'!G68 -> 0 | G4: P/B | N4: P/B
A5: P/Sales | B5: ='Multiple Valuation'!G19 -> 0 | C5: ='Multiple Valuation'!G35 -> 0 | D5: ='Multiple Valuation'!G51 -> 0 | E5: ='Multiple Valuation'!G67 -> 0 | G5: P/Sales | N5: P/Sales

Sheet Multiple Valuation
A1: Comparable Analysis
A3: Data
A5: Procter & Gamble | B5: Mil | D5: Source Detail | H5: Multiple of another firm
A6: Sales | H6: Apply this to P&G
A7: Net earnings attributable to P&G | H7: Obtain implied per share price (PG)
A8: Preferred dividends
A9: Book value of equity | H9: Implied Price PG / (Sales/share, PG) = P/S for competitor
A10: Weighted average shares outstanding | H10: Implied Price PG = (Sales/share,PG) x P/S for competitor
A11: Shares outstanding
A12: Sales per share
A13: Book value per share
A14: EPS
D16: Use the 10-K for period ending 12/31/2023
A17: Church & Dwight | B17: Mil | D17: Source Detail
A18: Sales | G18: Implied Price
A19: Net earnings attributable to parent | F19: Price-to-Sales
A20: Preferred dividends | F20: Price-to-Book
A21: Book value of equity | F21: Price-to-Earnings
A22: Weighted average shares outstanding
A23: Shares outstanding | F23: The above "implied prices" are for Procter & Gamble
A24: Sales per share
A25: Book value per share
A26: EPS
A27: Share price
A28: Price-to-Sales ratio
A29: Price-to-Earnings ratio
A30: Price-to-Book ratio
D32: Use the 10-K for period ending 12/31/2023
A33: STEPAN | B33: Mil | D33: Source Detail
A34: Sales | G34: Implied Price
A35: Net earnings attributable to parent | F35: Price-to-Sales
A36: Preferred dividends | F36: Price-to-Book
A37: Book value of equity | F37: Price-to-Earnings
A38: Weighted average shares outstanding
A39: Shares outstanding | F39: The above "implied prices" are for Procter & Gamble
A40: Sales per share
A41: Book value per share
A42: EPS
A43: Share price
A44: Price-to-Sales ratio
...

Sheet WACC_Growth_Sensitivity-->

Sheet WACC and Growth
A1: WACC, P&G
A2: WACC = D/V x Rd (1-T) + E/V x Re + P/V x Rp
A4: V = D + E + P | N4: This sensitivity table will be used for Case 4 only and will be required for Case 4 only!
A6: Market value of debt | C6: Pull from MV Debt and Weighted YTM worksheet
A7: Market value of equity | C7: Pull the price from the stock return sheet; multiply by shares o/s | O7: WACC
A8: Preferred Equity | C8: Pull the book value (balance sheet) value of preferred stock at t =0 | O8: ='DCF Analysis'!D22 -> 0 | P8: 0.04 | Q8: 0.045 | R8: 0.05 | S8: 0.055 | T8: 0.06 | U8: 0.065 | V8: 0.07 | W8: 0.075 | X8: 0.08
A9: Rd | C9: Pull from MV Debt and Weighted YTM worksheet | O9: 0.015
A10: Re | C10: Pull from Required return Equity worksheet | O10: 0.0175
A11: Rp | C11: Preferred dividends divided by Preferred equity | O11: 0.02
A12: Tax rate | O12: 0.0225
A13: WACC | C13: =_xlfn.FORMULATEXT(B13) -> #N/A | O13: 0.025
O14: 0.0275
O15: 0.03
A16: Shares outstanding | C16: Pull from Multiple Valuation Worksheet | O16: 0.0325
A17: Per share price | C17: Pull from Beta computation worksheet
A19: Growth in FCF | N19: This sensitivity table will be used for Case 4 only and will be required for Case 4 only!
A20: Growth | B20: 0.025

Sheet MV Debt and Weighted YTM (Rd)
A1: Procter & Gamble Long and Short Term Debt (book values from 10-K)
A5: As of June 30 | D5: Year Maturity | E5: Coupon (%) | F5: Book Value | G5: Price | H5: Market value | I5: Weight | J5: YTM (%) | K5: YTM x Weight
A6: LONG-TERM DEBT
A9: 0.50% EUR note due October 2024 | D9: 2024 | E9: 0.005 | F9: 534 | G9: {=_xlfn.XLOOKUP(D9&E9,'Debt details'!D$2:D$31&'Debt details'!C$2:C$31,'Debt details'!E$2:E$31)} -> 99.982
A10: 0.63% EUR note due October 2024 | D10: 2024 | E10: 0.00625 | F10: 855 | G10: {=_xlfn.XLOOKUP(D10&E10,'Debt details'!D$2:D$31&'Debt details'!C$2:C$31,'Debt details'!E$2:E$31)} -> 99.981
A11: 0.55% USD note due October 2025 | D11: 2025 | E11: 0.0055 | F11: 1000 | G11: {=_xlfn.XLOOKUP(D11&E11,'Debt details'!D$2:D$31&'Debt details'!C$2:C$31,'Debt details'!E$2:E$31)} -> 94.3061
A12: 4.10% USD note due January 2026 | D12: 2026 | E12: 0.041 | F12: 650 | G12: {=_xlfn.XLOOKUP(D12&E12,'Debt details'!D$2:D$31&'Debt details'!C$2:C$31,'Debt details'!E$2:E$31)} -> 99.77589
A13: 2.70% USD note due February 2026 | D13: 2026 | E13: 0.027 | F13: 600 | G13: {=_xlfn.XLOOKUP(D13&E13,'Debt details'!D$2:D$31&'Debt details'!C$2:C$31,'Debt details'!E$2:E$31)} -> 96.5881
A14: 1.00% USD note due April 2026 | D14: 2026 | E14: 0.01 | F14: 1000 | G14: {=_xlfn.XLOOKUP(D14&E14,'Debt details'!D$2:D$31&'Debt details'!C$2:C$31,'Debt details'!E$2:E$31)} -> 93.43159
A15: 3.25% EUR note due August 2026 | D15: 2026 | E15: 0.0325 | F15: 695 | G15: {=_xlfn.XLOOKUP(D15&E15,'Debt details'!D$2:D$31&'Debt details'!C$2:C$31,'Debt details'!E$2:E$31)} -> 99.977
A16: 2.45% USD note due November 2026 | D16: 2026 | E16: 0.0245 | F16: 875 | G16: {=_xlfn.XLOOKUP(D16&E16,'Debt details'!D$2:D$31&'Debt details'!C$2:C$31,'Debt details'!E$2:E$31)} -> 94.6889
A17: 1.90% USD note due February 2027 | D17: 2027 | E17: 0.019 | F17: 1000 | G17: {=_xlfn.XLOOKUP(D17&E17,'Debt details'!D$2:D$31&'Debt details'!C$2:C$31,'Debt details'!E$2:E$31)} -> 93.07465
A18: 2.80% USD note due March 2027 | D18: 2027 | E18: 0.028 | F18: 500 | G18: {=_xlfn.XLOOKUP(D18&E18,'Debt details'!D$2:D$31&'Debt details'!C$2:C$31,'Debt details'!E$2:E$31)} -> 95.03116
A19: 4.88% EUR note due May 2027 | D19: 2027 | E19: 0.04875 | F19: 1069 | G19: {=_xlfn.XLOOKUP(D19&E19,'Debt details'!D$2:D$31&'Debt details'!C$2:C$31,'Debt details'!E$2:E$31)} -> 104.566
A20: 2.85% USD note due August 2027 | D20: 2027 | E20: 0.0285 | F20: 750 | G20: {=_xlfn.XLOOKUP(D20&E20,'Debt details'!D$2:D$31&'Debt details'!C$2:C$31,'Debt details'!E$2:E$31)} -> 94.453
... A38: 0.90% EUR note due November 2041 | D38: 2041 | E38: 0.009 | F38: 641 | G38: {=_xlfn.XLOOKUP(D38&E38,'Debt details'!D$2:D$31&'Debt details'!C$2:C$31,'Debt details'!E$2:E$31)} -> 66.927
A39: All other long-term debt | F39: 5550 | G39: 100
A40: Current portion of long-term debt | F40: -3838
A41: TOTL | F41: =SUM(F7:F40) -> 25269 | H41: =SUM(H7:H40) -> 0 | I41: =SUM(I7:I40) -> 0 | K41: =SUM(K7:K40) -> 0 | L41: weighted average YTM for long-term debt
A44: Short Term Debt | D44: Year of Maturity | E44: Rate (%) | F44: Book value | G44: Price | H44: Market value | I44: Weight | J44: YTM (%) | K44: YTM x Weight
A45: Commercial paper | D45: 2024 | E45: 3.7 | F45: 3327 | G45: 100 | J45: 3.7
A46: Other short term debt | D46: 2024 | E46: 3.7 | F46: 26 | G46: 100 | J46: 3.7
A47: Current portion long-term debt | D47: 2024 | E47: 3.7 | F47: 3838 | G47: 100 | J47: 3.7
A48: Total short-term debt | F48: =SUM(F45:F47) -> 7191 | H48: =SUM(H45:H47) -> 0 | I48: =SUM(I45:I47) -> 0 | K48: =SUM(K45:K47) -> 0 | L48: weighted average YTM for short-term debt
A51: Summary and Computation of Weighted Average YTM (Overall)
B52: MV | C52: Weight | D52: YTM (%) | E52: Wt x YTM
A53: LT debt | B53: =H41 -> 0 | C53: =B53/B$55 -> #DIV/0! | D53: =K41 -> 0 | E53: =D53*C53 -> #DIV/0!
A54: ST debt | B54: =H48 -> 0 | C54: =B54/B$55 -> #DIV/0! | D54: =K48 -> 0 | E54: =D54*C54 -> #DIV/0!
A55: Total Debt | B55: =SUM(B53:B54) -> 0 | C55: =SUM(C53:C54) -> #DIV/0! | E55: =SUM(E53:E54) -> #DIV/0! | F55: Total weighted YTM

Sheet Debt details
A1: Name | B1: Ticker | C1: Coupon | D1: Maturity Year | E1: Price (%) | F1: Yield (%)
A2: Procter & Gamble Co/The | B2: PG | C2: 0.005 | D2: 2024 | E2: 99.982 | F2: 3.765315
A3: Procter & Gamble Co/The | B3: PG | C3: 0.00625 | D3: 2024 | E3: 99.981 | F3: 3.755442 | H3: Source: Bloomberg on the closest trading date to 6/28/2024
A4: Procter & Gamble Co/The | B4: PG | C4: 0.0055 | D4: 2025 | E4: 94.3061 | F4: 5.036418
A5: Procter & Gamble Co/The | B5: PG | C5: 0.041 | D5: 2026 | E5: 99.77589 | F5: 4.917997
A6: Procter & Gamble Co/The | B6: PG | C6: 0.027 | D6: 2026 | E6: 96.5881 | F6: 4.96186
A7: Procter & Gamble Co/The | B7: PG | C7: 0.01 | D7: 2026 | E7: 93.43159 | F7: 4.830463
A8: Procter & Gamble Co/The | B8: PG | C8: 0.0325 | D8: 2026 | E8: 99.977 | F8: 3.259545
A9: Procter & Gamble Co/The | B9: PG | C9: 0.0245 | D9: 2026 | E9: 94.6889 | F9: 4.878887
A10: Procter & Gamble Co/The | B10: PG | C10: 0.019 | D10: 2027 | E10: 93.07465 | F10: 4.780962
A11: Procter & Gamble Co/The | B11: PG | C11: 0.028 | D11: 2027 | E11: 95.03116 | F11: 4.758547
A12: Procter & Gamble Co/The | B12: PG | C12: 0.04875 | D12: 2027 | E12: 104.566 | F12: 3.174879
A13: Procter & Gamble Co/The | B13: PG | C13: 0.0285 | D13: 2027 | E13: 94.453 | F13: 4.789296
A14: Procter & Gamble Co/The | B14: PG | C14: 0.0395 | D14: 2028 | E14: 97.89587 | F14: 4.595053
A15: Procter & Gamble Co/The | B15: PG | C15: 0.0315 | D15: 2028 | E15: 99.853 | F15: 3.189427
... A31: Procter & Gamble Co/The | B31: PG | C31: 0.009 | D31: 2041 | E31: 66.927 | F31: 3.469812

Sheet Required return equity, (Re)
A1: Required return on equity
A2: Re = Rf + Beta (Rm - Rf)
A4: Beta computation period | B4: 60 | F4: Beta computation period
A5: Choice of market returns | B5: S&P | F5: 60
F6: 120
F7: Market returns
A8: Risk-free rate | B8: 0.0451 | D8: 30 year treasury 6/28/2024 (www.treasury.gov) | F8: VW
A9: Beta | D9: Pull from Beta Worksheet (Write if statement, or Index/Match for all possibilities of B4 and B5 above) | F9: EW
A10: Market risk premium | B10: 0.055 | D10: Pablo Fernandez Survey 2024 | F10: S&P
A11: Re | D11: =_xlfn.FORMULATEXT(B11) -> #N/A

Sheet Beta computation
A1: PERMNO | B1: Names Date | C1: CUSIP | D1: Ticker Symbol | E1: Company Name | F1: PERMCO | G1: CUSIP Header | H1: Price or Bid/Ask Average | I1: Returns | J1: Value-Weighted Return-incl. dividends | K1: Equal-Weighted Return-incl. dividends | L1: Return on the S&P 500 Index | M1: Formatted date | N1: Returns for Series 1 | O1: VW Series 1 | P1: EW Series 1 | Q1: S&P Series 1 | R1: Returns for Series 2 | S1: VW Series 2 | T1: EW Series 2 | U1: S&P Series 2 | V1: 10K date | W1: 10k month | X1: 10 k day | Y1: 10 k year | Z1: eom based on 10K | AA1: one month prior | AB1: one month prior, EOM
A2: 18163 | B2: 40939 | C2: 74271810 | D2: PG | E2: PROCTER & GAMBLE CO | F2: 21446 | G2: 74271810 | H2: 63.040001 | I2: -0.047144331 | J2: 0.05410639 | K2: 0.085342 | L2: 0.04358302 | M2: =B2 -> 40939 | N2: =IF(AND(($W$12-4)<=$M2,($W$13)>=($M2-4)),I2," ") -> #VALUE! | O2: =IF(AND(($W$12-4)<=$M2,($W$13)>=($M2-4)),J2," ") -> #VALUE! | P2: =IF(AND(($W$12-4)<=$M2,($W$13)>=($M2-4)),K2," ") -> #VALUE! | Q2: =IF(AND(($W$12-4)<=$M2,($W$13)>=($M2-4)),L2," ") -> #VALUE! | R2: =IF(AND(($W$15-4)<=$M2,($W$16)>=($M2-4)),I2," ") -> #VALUE! | S2: =IF(AND(($W$15-4)<=$M2,($W$16)>=($M2-4)),J2," ") -> #VALUE! | T2: =IF(AND(($W$15-4)<=$M2,($W$16)>=($M2-4)),K2," ") -> #VALUE! | U2: =IF(AND(($W$15-4)<=$M2,($W$16)>=($M2-4)),L2," ") -> #VALUE! | V2: 45473 | W2: =MONTH(V2) -> 6 | X2: =DAY(V2) -> 30 | Y2: =YEAR(V2) -> 2024 | Z2: =DATE(Y2,W2,X2) -> 45473 | AA2: =DATE(Y2,(W2-1),1) -> 45413 | AB2: =EOMONTH(AA2,0) -> 45443
A3: 18163 | B3: 40968 | C3: 74271810 | D3: PG | E3: PROCTER & GAMBLE CO | F3: 21446 | G3: 74271810 | H3: 67.620003 | I3: 0.07265231 | J3: 0.04122525 | K3: 0.03649384 | L3: 0.04058945 | M3: =B3 -> 40968 | N3: =IF(AND(($W$12-4)<=$M3,($W$13)>=($M3-4)),I3," ") -> #VALUE! | O3: =IF(AND(($W$12-4)<=$M3,($W$13)>=($M3-4)),J3," ") -> #VALUE! | P3: =IF(AND(($W$12-4)<=$M3,($W$13)>=($M3-4)),K3," ") -> #VALUE! | Q3: =IF(AND(($W$12-4)<=$M3,($W$13)>=($M3-4)),L3," ") -> #VALUE! | R3: =IF(AND(($W$15-4)<=$M3,($W$16)>=($M3-4)),I3," ") -> #VALUE! | S3: =IF(AND(($W$15-4)<=$M3,($W$16)>=($M3-4)),J3," ") -> #VALUE! | T3: =IF(AND(($W$15-4)<=$M3,($W$16)>=($M3-4)),K3," ") -> #VALUE! | U3: =IF(AND(($W$15-4)<=$M3,($W$16)>=($M3-4)),L3," ") -> #VALUE!
A4: 18163 | B4: 40998 | C4: 74271810 | D4: PG | E4: PROCTER & GAMBLE CO | F4: 21446 | G4: 74271810 | H4: 67.209999 | I4: -0.0060633486 | J4: 0.02402032 | K4: 0.01760839 | L4: 0.03133238 | M4: =B4 -> 40998 | N4: =IF(AND(($W$12-4)<=$M4,($W$13)>=($M4-4)),I4," ") -> #VALUE! | O4: =IF(AND(($W$12-4)<=$M4,($W$13)>=($M4-4)),J4," ") -> #VALUE! | P4: =IF(AND(($W$12-4)<=$M4,($W$13)>=($M4-4)),K4," ") -> #VALUE! | Q4: =IF(AND(($W$12-4)<=$M4,($W$13)>=($M4-4)),L4," ") -> #VALUE! | R4: =IF(AND(($W$15-4)<=$M4,($W$16)>=($M4-4)),I4," ") -> #VALUE! | S4: =IF(AND(($W$15-4)<=$M4,($W$16)>=($M4-4)),J4," ") -> #VALUE! | T4: =IF(AND(($W$15-4)<=$M4,($W$16)>=($M4-4)),K4," ") -> #VALUE! | U4: =IF(AND(($W$15-4)<=$M4,($W$16)>=($M4-4)),L4," ") -> #VALUE! | Z4: Date | AA4: Stock price
A5: 18163 | B5: 41029 | C5: 74271810 | D5: PG | E5: PROCTER & GAMBLE CO | F5: 21446 | G5: 74271810 | H5: 63.639999 | I5: -0.044755243 | J5: -0.006828595 | K5: -0.009106334 | L5: -0.007497497 | M5: =B5 -> 41029 | N5: =IF(AND(($W$12-4)<=$M5,($W$13)>=($M5-4)),I5," ") -> #VALUE! | O5: =IF(AND(($W$12-4)<=$M5,($W$13)>=($M5-4)),J5," ") -> #VALUE! | P5: =IF(AND(($W$12-4)<=$M5,($W$13)>=($M5-4)),K5," ") -> #VALUE! | Q5: =IF(AND(($W$12-4)<=$M5,($W$13)>=($M5-4)),L5," ") -> #VALUE! | R5: =IF(AND(($W$15-4)<=$M5,($W$16)>=($M5-4)),I5," ") -> #VALUE! | S5: =IF(AND(($W$15-4)<=$M5,($W$16)>=($M5-4)),J5," ") -> #VALUE! | T5: =IF(AND(($W$15-4)<=$M5,($W$16)>=($M5-4)),K5," ") -> #VALUE! | U5: =IF(AND(($W$15-4)<=$M5,($W$16)>=($M5-4)),L5," ") -> #VALUE! | V5: Month to use for last trade date | W5: 45291 | Y5: Stock price closest to date of 10-K without going past | Z5: 45471 | AA5: 164.92 | AB5: Yahoo Close Price (not adjusted close)
A6: 18163 | B6: 41060 | C6: 74271810 | D6: PG | E6: PROCTER & GAMBLE CO | F6: 21446 | G6: 74271810 | H6: 62.290001 | I6: -0.021213049 | J6: -0.06559022 | K6: -0.0684181 | L6: -0.06265067 | M6: =B6 -> 41060 | N6: =IF(AND(($W$12-4)<=$M6,($W$13)>=($M6-4)),I6," ") -> #VALUE! | O6: =IF(AND(($W$12-4)<=$M6,($W$13)>=($M6-4)),J6," ") -> #VALUE! | P6: =IF(AND(($W$12-4)<=$M6,($W$13)>=($M6-4)),K6," ") -> #VALUE! | Q6: =IF(AND(($W$12-4)<=$M6,($W$13)>=($M6-4)),L6," ") -> #VALUE! | R6: =IF(AND(($W$15-4)<=$M6,($W$16)>=($M6-4)),I6," ") -> #VALUE! | S6: =IF(AND(($W$15-4)<=$M6,($W$16)>=($M6-4)),J6," ") -> #VALUE! | T6: =IF(AND(($W$15-4)<=$M6,($W$16)>=($M6-4)),K6," ") -> #VALUE! | U6: =IF(AND(($W$15-4)<=$M6,($W$16)>=($M6-4)),L6," ") -> #VALUE!
A7: 18163 | B7: 41089 | C7: 74271810 | D7: PG | E7: PROCTER & GAMBLE CO | F7: 21446 | G7: 74271810 | H7: 61.25 | I7: -0.016696114 | J7: 0.03815087 | K7: 0.03418799 | L7: 0.03955492 | M7: =B7 -> 41089 | N7: =IF(AND(($W$12-4)<=$M7,($W$13)>=($M7-4)),I7," ") -> #VALUE! | O7: =IF(AND(($W$12-4)<=$M7,($W$13)>=($M7-4)),J7," ") -> #VALUE! | P7: =IF(AND(($W$12-4)<=$M7,($W$13)>=($M7-4)),K7," ") -> #VALUE! | Q7: =IF(AND(($W$12-4)<=$M7,($W$13)>=($M7-4)),L7," ") -> #VALUE! | R7: =IF(AND(($W$15-4)<=$M7,($W$16)>=($M7-4)),I7," ") -> #VALUE! | S7: =IF(AND(($W$15-4)<=$M7,($W$16)>=($M7-4)),J7," ") -> #VALUE! | T7: =IF(AND(($W$15-4)<=$M7,($W$16)>=($M7-4)),K7," ") -> #VALUE! | U7: =IF(AND(($W$15-4)<=$M7,($W$16)>=($M7-4)),L7," ") -> #VALUE! | V7: Months prior #1 | W7: 60 | Y7: I've hardcoded the price in AB5; nothing needed
A8: 18163 | B8: 41121 | C8: 74271810 | D8: PG | E8: PROCTER & GAMBLE CO | F8: 21446 | G8: 74271810 | H8: 64.540001 | I8: 0.062889807 | J8: 0.01030725 | K8: -0.003280566 | L8: 0.01259764 | M8: =B8 -> 41121 | N8: =IF(AND(($W$12-4)<=$M8,($W$13)>=($M8-4)),I8," ") -> #VALUE! | O8: =IF(AND(($W$12-4)<=$M8,($W$13)>=($M8-4)),J8," ") -> #VALUE! | P8: =IF(AND(($W$12-4)<=$M8,($W$13)>=($M8-4)),K8," ") -> #VALUE! | Q8: =IF(AND(($W$12-4)<=$M8,($W$13)>=($M8-4)),L8," ") -> #VALUE! | R8: =IF(AND(($W$15-4)<=$M8,($W$16)>=($M8-4)),I8," ") -> #VALUE! | S8: =IF(AND(($W$15-4)<=$M8,($W$16)>=($M8-4)),J8," ") -> #VALUE! | T8: =IF(AND(($W$15-4)<=$M8,($W$16)>=($M8-4)),K8," ") -> #VALUE! | U8: =IF(AND(($W$15-4)<=$M8,($W$16)>=($M8-4)),L8," ") -> #VALUE! | V8: Months prior #2 | W8: 120
A9: 18163 | B9: 41152 | C9: 74271810 | D9: PG | E9: PROCTER & GAMBLE CO | F9: 21446 | G9: 74271810 | H9: 67.190002 | I9: 0.041059829 | J9: 0.02631677 | K9: 0.02481905 | L9: 0.01976336 | M9: =B9 -> 41152 | N9: =IF(AND(($W$12-4)<=$M9,($W$13)>=($M9-4)),I9," ") -> #VALUE! | O9: =IF(AND(($W$12-4)<=$M9,($W$13)>=($M9-4)),J9," ") -> #VALUE! | P9: =IF(AND(($W$12-4)<=$M9,($W$13)>=($M9-4)),K9," ") -> #VALUE! | Q9: =IF(AND(($W$12-4)<=$M9,($W$13)>=($M9-4)),L9," ") -> #VALUE! | R9: =IF(AND(($W$15-4)<=$M9,($W$16)>=($M9-4)),I9," ") -> #VALUE! | S9: =IF(AND(($W$15-4)<=$M9,($W$16)>=($M9-4)),J9," ") -> #VALUE! | T9: =IF(AND(($W$15-4)<=$M9,($W$16)>=($M9-4)),K9," ") -> #VALUE! | U9: =IF(AND(($W$15-4)<=$M9,($W$16)>=($M9-4)),L9," ") -> #VALUE!
A10: 18163 | B10: 41180 | C10: 74271810 | D10: PG | E10: PROCTER & GAMBLE CO | F10: 21446 | G10: 74271810 | H10: 69.360001 | I10: 0.032296445 | J10: 0.02651327 | K10: 0.03492516 | L10: 0.02423609 | M10: =B10 -> 41180 | N10: =IF(AND(($W$12-4)<=$M10,($W$13)>=($M10-4)),I10," ") -> #VALUE! | O10: =IF(AND(($W$12-4)<=$M10,($W$13)>=($M10-4)),J10," ") -> #VALUE! | P10: =IF(AND(($W$12-4)<=$M10,($W$13)>=($M10-4)),K10," ") -> #VALUE! | Q10: =IF(AND(($W$12-4)<=$M10,($W$13)>=($M10-4)),L10," ") -> #VALUE! | R10: =IF(AND(($W$15-4)<=$M10,($W$16)>=($M10-4)),I10," ") -> #VALUE! | S10: =IF(AND(($W$15-4)<=$M10,($W$16)>=($M10-4)),J10," ") -> #VALUE! | T10: =IF(AND(($W$15-4)<=$M10,($W$16)>=($M10-4)),K10," ") -> #VALUE! | U10: =IF(AND(($W$15-4)<=$M10,($W$16)>=($M10-4)),L10," ") -> #VALUE!
A11: 18163 | B11: 41213 | C11: 74271810 | D11: PG | E11: PROCTER & GAMBLE CO | F11: 21446 | G11: 74271810 | H11: 69.239998 | I11: 0.0063725091 | J11: -0.0140545 | K11: -0.01347699 | L11: -0.0197894 | M11: =B11 -> 41213 | N11: =IF(AND(($W$12-4)<=$M11,($W$13)>=($M11-4)),I11," ") -> #VALUE! | O11: =IF(AND(($W$12-4)<=$M11,($W$13)>=($M11-4)),J11," ") -> #VALUE! | P11: =IF(AND(($W$12-4)<=$M11,($W$13)>=($M11-4)),K11," ") -> #VALUE! | Q11: =IF(AND(($W$12-4)<=$M11,($W$13)>=($M11-4)),L11," ") -> #VALUE! | R11: =IF(AND(($W$15-4)<=$M11,($W$16)>=($M11-4)),I11," ") -> #VALUE! | S11: =IF(AND(($W$15-4)<=$M11,($W$16)>=($M11-4)),J11," ") -> #VALUE! | T11: =IF(AND(($W$15-4)<=$M11,($W$16)>=($M11-4)),K11," ") -> #VALUE! | U11: =IF(AND(($W$15-4)<=$M11,($W$16)>=($M11-4)),L11," ") -> #VALUE!
A12: 18163 | B12: 41243 | C12: 74271810 | D12: PG | E12: PROCTER & GAMBLE CO | F12: 21446 | G12: 74271810 | H12: 69.830002 | I12: 0.0085211433 | J12: 0.006216758 | K12: 0.002790037 | L12: 0.002846703 | M12: =B12 -> 41243 | N12: =IF(AND(($W$12-4)<=$M12,($W$13)>=($M12-4)),I12," ") -> #VALUE! | O12: =IF(AND(($W$12-4)<=$M12,($W$13)>=($M12-4)),J12," ") -> #VALUE! | P12: =IF(AND(($W$12-4)<=$M12,($W$13)>=($M12-4)),K12," ") -> #VALUE! | Q12: =IF(AND(($W$12-4)<=$M12,($W$13)>=($M12-4)),L12," ") -> #VALUE! | R12: =IF(AND(($W$15-4)<=$M12,($W$16)>=($M12-4)),I12," ") -> #VALUE! | S12: =IF(AND(($W$15-4)<=$M12,($W$16)>=($M12-4)),J12," ") -> #VALUE! | T12: =IF(AND(($W$15-4)<=$M12,($W$16)>=($M12-4)),K12," ") -> #VALUE! | U12: =IF(AND(($W$15-4)<=$M12,($W$16)>=($M12-4)),L12," ") -> #VALUE! | V12: Series 1 Beg | X12: =_xlfn.FORMULATEXT(W12) -> #N/A
A13: 18163 | B13: 41274 | C13: 74271810 | D13: PG | E13: PROCTER & GAMBLE CO | F13: 21446 | G13: 74271810 | H13: 67.889999 | I13: -0.02778179 | J13: 0.01256859 | K13: 0.02187174 | L13: 0.00706831 | M13: =B13 -> 41274 | N13: =IF(AND(($W$12-4)<=$M13,($W$13)>=($M13-4)),I13," ") -> #VALUE! | O13: =IF(AND(($W$12-4)<=$M13,($W$13)>=($M13-4)),J13," ") -> #VALUE! | P13: =IF(AND(($W$12-4)<=$M13,($W$13)>=($M13-4)),K13," ") -> #VALUE! | Q13: =IF(AND(($W$12-4)<=$M13,($W$13)>=($M13-4)),L13," ") -> #VALUE! | R13: =IF(AND(($W$15-4)<=$M13,($W$16)>=($M13-4)),I13," ") -> #VALUE! | S13: =IF(AND(($W$15-4)<=$M13,($W$16)>=($M13-4)),J13," ") -> #VALUE! | T13: =IF(AND(($W$15-4)<=$M13,($W$16)>=($M13-4)),K13," ") -> #VALUE! | U13: =IF(AND(($W$15-4)<=$M13,($W$16)>=($M13-4)),L13," ") -> #VALUE! | V13: Series 1 End | W13: 45291
A14: 18163 | B14: 41305 | C14: 74271810 | D14: PG | E14: PROCTER & GAMBLE CO | F14: 21446 | G14: 74271810 | H14: 75.160004 | I14: 0.11536315 | J14: 0.0541421 | K14: 0.06350936 | L14: 0.05042806 | M14: =B14 -> 41305 | N14: =IF(AND(($W$12-4)<=$M14,($W$13)>=($M14-4)),I14," ") -> #VALUE! | O14: =IF(AND(($W$12-4)<=$M14,($W$13)>=($M14-4)),J14," ") -> #VALUE! | P14: =IF(AND(($W$12-4)<=$M14,($W$13)>=($M14-4)),K14," ") -> #VALUE! | Q14: =IF(AND(($W$12-4)<=$M14,($W$13)>=($M14-4)),L14," ") -> #VALUE! | R14: =IF(AND(($W$15-4)<=$M14,($W$16)>=($M14-4)),I14," ") -> #VALUE! | S14: =IF(AND(($W$15-4)<=$M14,($W$16)>=($M14-4)),J14," ") -> #VALUE! | T14: =IF(AND(($W$15-4)<=$M14,($W$16)>=($M14-4)),K14," ") -> #VALUE! | U14: =IF(AND(($W$15-4)<=$M14,($W$16)>=($M14-4)),L14," ") -> #VALUE!
A15: 18163 | B15: 41333 | C15: 74271810 | D15: PG | E15: PROCTER & GAMBLE CO | F15: 21446 | G15: 74271810 | H15: 76.18 | I15: 0.013571003 | J15: 0.008282192 | K15: 0.003490682 | L15: 0.0110606 | M15: =B15 -> 41333 | N15: =IF(AND(($W$12-4)<=$M15,($W$13)>=($M15-4)),I15," ") -> #VALUE! | O15: =IF(AND(($W$12-4)<=$M15,($W$13)>=($M15-4)),J15," ") -> #VALUE! | P15: =IF(AND(($W$12-4)<=$M15,($W$13)>=($M15-4)),K15," ") -> #VALUE! | Q15: =IF(AND(($W$12-4)<=$M15,($W$13)>=($M15-4)),L15," ") -> #VALUE! | R15: =IF(AND(($W$15-4)<=$M15,($W$16)>=($M15-4)),I15," ") -> #VALUE! | S15: =IF(AND(($W$15-4)<=$M15,($W$16)>=($M15-4)),J15," ") -> #VALUE! | T15: =IF(AND(($W$15-4)<=$M15,($W$16)>=($M15-4)),K15," ") -> #VALUE! | U15: =IF(AND(($W$15-4)<=$M15,($W$16)>=($M15-4)),L15," ") -> #VALUE! | V15: Series 2 Beg | X15: =_xlfn.FORMULATEXT(W15) -> #N/A
A16: 18163 | B16: 41361 | C16: 74271810 | D16: PG | E16: PROCTER & GAMBLE CO | F16: 21446 | G16: 74271810 | H16: 77.059998 | I16: 0.011551552 | J16: 0.03529461 | K16: 0.03141874 | L16: 0.0359878 | M16: =B16 -> 41361 | N16: =IF(AND(($W$12-4)<=$M16,($W$13)>=($M16-4)),I16," ") -> #VALUE! | O16: =IF(AND(($W$12-4)<=$M16,($W$13)>=($M16-4)),J16," ") -> #VALUE! | P16: =IF(AND(($W$12-4)<=$M16,($W$13)>=($M16-4)),K16," ") -> #VALUE! | Q16: =IF(AND(($W$12-4)<=$M16,($W$13)>=($M16-4)),L16," ") -> #VALUE! | R16: =IF(AND(($W$15-4)<=$M16,($W$16)>=($M16-4)),I16," ") -> #VALUE! | S16: =IF(AND(($W$15-4)<=$M16,($W$16)>=($M16-4)),J16," ") -> #VALUE! | T16: =IF(AND(($W$15-4)<=$M16,($W$16)>=($M16-4)),K16," ") -> #VALUE! | U16: =IF(AND(($W$15-4)<=$M16,($W$16)>=($M16-4)),L16," ") -> #VALUE! | V16: Series 2 End | W16: 45291
A17: 18163 | B17: 41394 | C17: 74271810 | D17: PG | E17: PROCTER & GAMBLE CO | F17: 21446 | G17: 74271810 | H17: 76.769997 | I17: 0.0040422925 | J17: 0.01493866 | K17: 0.002477191 | L17: 0.01808576 | M17: =B17 -> 41394 | N17: =IF(AND(($W$12-4)<=$M17,($W$13)>=($M17-4)),I17," ") -> #VALUE! | O17: =IF(AND(($W$12-4)<=$M17,($W$13)>=($M17-4)),J17," ") -> #VALUE! | P17: =IF(AND(($W$12-4)<=$M17,($W$13)>=($M17-4)),K17," ") -> #VALUE! | Q17: =IF(AND(($W$12-4)<=$M17,($W$13)>=($M17-4)),L17," ") -> #VALUE! | R17: =IF(AND(($W$15-4)<=$M17,($W$16)>=($M17-4)),I17," ") -> #VALUE! | S17: =IF(AND(($W$15-4)<=$M17,($W$16)>=($M17-4)),J17," ") -> #VALUE! | T17: =IF(AND(($W$15-4)<=$M17,($W$16)>=($M17-4)),K17," ") -> #VALUE! | U17: =IF(AND(($W$15-4)<=$M17,($W$16)>=($M17-4)),L17," ") -> #VALUE!
A18: 18163 | B18: 41425 | C18: 74271810 | D18: PG | E18: PROCTER & GAMBLE CO | F18: 21446 | G18: 74271810 | H18: 76.760002 | I18: -0.00013018766 | J18: 0.01912778 | K18: 0.02398535 | L18: 0.02076278 | M18: =B18 -> 41425 | N18: =IF(AND(($W$12-4)<=$M18,($W$13)>=($M18-4)),I18," ") -> #VALUE! | O18: =IF(AND(($W$12-4)<=$M18,($W$13)>=($M18-4)),J18," ") -> #VALUE! | P18: =IF(AND(($W$12-4)<=$M18,($W$13)>=($M18-4)),K18," ") -> #VALUE! | Q18: =IF(AND(($W$12-4)<=$M18,($W$13)>=($M18-4)),L18," ") -> #VALUE! | R18: =IF(AND(($W$15-4)<=$M18,($W$16)>=($M18-4)),I18," ") -> #VALUE! | S18: =IF(AND(($W$15-4)<=$M18,($W$16)>=($M18-4)),J18," ") -> #VALUE! | T18: =IF(AND(($W$15-4)<=$M18,($W$16)>=($M18-4)),K18," ") -> #VALUE! | U18: =IF(AND(($W$15-4)<=$M18,($W$16)>=($M18-4)),L18," ") -> #VALUE! | V18: Time/Market | W18: Betas | Y18: We regress Company returns on Market Index returns:
A19: 18163 | B19: 41453 | C19: 74271810 | D19: PG | E19: PROCTER & GAMBLE CO | F19: 21446 | G19: 74271810 | H19: 76.989998 | I19: 0.0029962966 | J19: -0.01507222 | K19: -0.01301197 | L19: -0.01499933 | M19: =B19 -> 41453 | N19: =IF(AND(($W$12-4)<=$M19,($W$13)>=($M19-4)),I19," ") -> #VALUE! | O19: =IF(AND(($W$12-4)<=$M19,($W$13)>=($M19-4)),J19," ") -> #VALUE! | P19: =IF(AND(($W$12-4)<=$M19,($W$13)>=($M19-4)),K19," ") -> #VALUE! | Q19: =IF(AND(($W$12-4)<=$M19,($W$13)>=($M19-4)),L19," ") -> #VALUE! | R19: =IF(AND(($W$15-4)<=$M19,($W$16)>=($M19-4)),I19," ") -> #VALUE! | S19: =IF(AND(($W$15-4)<=$M19,($W$16)>=($M19-4)),J19," ") -> #VALUE! | T19: =IF(AND(($W$15-4)<=$M19,($W$16)>=($M19-4)),K19," ") -> #VALUE! | U19: =IF(AND(($W$15-4)<=$M19,($W$16)>=($M19-4)),L19," ") -> #VALUE! | V19: 60 month VW | X19: =_xlfn.FORMULATEXT(W19) -> #N/A | Y19: Returns (P&G) = β1 Market returns
A20: 18163 | B20: 41486 | C20: 74271810 | D20: PG | E20: PROCTER & GAMBLE CO | F20: 21446 | G20: 74271810 | H20: 80.300003 | I20: 0.050805368 | J20: 0.05265804 | K20: 0.05489828 | L20: 0.04946211 | M20: =B20 -> 41486 | N20: =IF(AND(($W$12-4)<=$M20,($W$13)>=($M20-4)),I20," ") -> #VALUE! | O20: =IF(AND(($W$12-4)<=$M20,($W$13)>=($M20-4)),J20," ") -> #VALUE! | P20: =IF(AND(($W$12-4)<=$M20,($W$13)>=($M20-4)),K20," ") -> #VALUE! | Q20: =IF(AND(($W$12-4)<=$M20,($W$13)>=($M20-4)),L20," ") -> #VALUE! | R20: =IF(AND(($W$15-4)<=$M20,($W$16)>=($M20-4)),I20," ") -> #VALUE! | S20: =IF(AND(($W$15-4)<=$M20,($W$16)>=($M20-4)),J20," ") -> #VALUE! | T20: =IF(AND(($W$15-4)<=$M20,($W$16)>=($M20-4)),K20," ") -> #VALUE! | U20: =IF(AND(($W$15-4)<=$M20,($W$16)>=($M20-4)),L20," ") -> #VALUE! | V20: 60 month EW | X20: =_xlfn.FORMULATEXT(W20) -> #N/A | Y20: Where PG returns = dependent variable
A21: 18163 | B21: 41516 | C21: 74271810 | D21: PG | E21: PROCTER & GAMBLE CO | F21: 21446 | G21: 74271810 | H21: 77.889999 | I21: -0.030012498 | J21: -0.02575004 | K21: -0.01727787 | L21: -0.03129801 | M21: =B21 -> 41516 | N21: =IF(AND(($W$12-4)<=$M21,($W$13)>=($M21-4)),I21," ") -> #VALUE! | O21: =IF(AND(($W$12-4)<=$M21,($W$13)>=($M21-4)),J21," ") -> #VALUE! | P21: =IF(AND(($W$12-4)<=$M21,($W$13)>=($M21-4)),K21," ") -> #VALUE! | Q21: =IF(AND(($W$12-4)<=$M21,($W$13)>=($M21-4)),L21," ") -> #VALUE! | R21: =IF(AND(($W$15-4)<=$M21,($W$16)>=($M21-4)),I21," ") -> #VALUE! | S21: =IF(AND(($W$15-4)<=$M21,($W$16)>=($M21-4)),J21," ") -> #VALUE! | T21: =IF(AND(($W$15-4)<=$M21,($W$16)>=($M21-4)),K21," ") -> #VALUE! | U21: =IF(AND(($W$15-4)<=$M21,($W$16)>=($M21-4)),L21," ") -> #VALUE! | V21: 60 month S&P | X21: =_xlfn.FORMULATEXT(W21) -> #N/A | Y21: Market returns = independent variable.
A22: 18163 | B22: 41547 | C22: 74271810 | D22: PG | E22: PROCTER & GAMBLE CO | F22: 21446 | G22: 74271810 | H22: 75.589996 | I22: -0.029528862 | J22: 0.03749721 | K22: 0.05182836 | L22: 0.02974948 | M22: =B22 -> 41547 | N22: =IF(AND(($W$12-4)<=$M22,($W$13)>=($M22-4)),I22," ") -> #VALUE! | O22: =IF(AND(($W$12-4)<=$M22,($W$13)>=($M22-4)),J22," ") -> #VALUE! | P22: =IF(AND(($W$12-4)<=$M22,($W$13)>=($M22-4)),K22," ") -> #VALUE! | Q22: =IF(AND(($W$12-4)<=$M22,($W$13)>=($M22-4)),L22," ") -> #VALUE! | R22: =IF(AND(($W$15-4)<=$M22,($W$16)>=($M22-4)),I22," ") -> #VALUE! | S22: =IF(AND(($W$15-4)<=$M22,($W$16)>=($M22-4)),J22," ") -> #VALUE! | T22: =IF(AND(($W$15-4)<=$M22,($W$16)>=($M22-4)),K22," ") -> #VALUE! | U22: =IF(AND(($W$15-4)<=$M22,($W$16)>=($M22-4)),L22," ") -> #VALUE! | V22: 120 month VW | X22: =_xlfn.FORMULATEXT(W22) -> #N/A | Y22: We will use the slope function in excel
A23: 18163 | B23: 41578 | C23: 74271810 | D23: PG | E23: PROCTER & GAMBLE CO | F23: 21446 | G23: 74271810 | H23: 80.75 | I23: 0.076220453 | J23: 0.03988853 | K23: 0.02576191 | L23: 0.04459576 | M23: =B23 -> 41578 | N23: =IF(AND(($W$12-4)<=$M23,($W$13)>=($M23-4)),I23," ") -> #VALUE! | O23: =IF(AND(($W$12-4)<=$M23,($W$13)>=($M23-4)),J23," ") -> #VALUE! | P23: =IF(AND(($W$12-4)<=$M23,($W$13)>=($M23-4)),K23," ") -> #VALUE! | Q23: =IF(AND(($W$12-4)<=$M23,($W$13)>=($M23-4)),L23," ") -> #VALUE! | R23: =IF(AND(($W$15-4)<=$M23,($W$16)>=($M23-4)),I23," ") -> #VALUE! | S23: =IF(AND(($W$15-4)<=$M23,($W$16)>=($M23-4)),J23," ") -> #VALUE! | T23: =IF(AND(($W$15-4)<=$M23,($W$16)>=($M23-4)),K23," ") -> #VALUE! | U23: =IF(AND(($W$15-4)<=$M23,($W$16)>=($M23-4)),L23," ") -> #VALUE! | V23: 120 month EW | X23: =_xlfn.FORMULATEXT(W23) -> #N/A | Y23: Prove that the covariance divided by variance returns same value
